Workbook

Sheet Dashboard
A1: Stress Test Dashboard
A3: Use the test sheets to record actual behavior. This dashboard updates from Comparison Status entries.
A5: Metric | B5: Value | D5: TEST INVENTORY
A6: Total planned tests | B6: =COUNTA('Ranking Stress Tests'!$A$6:$A$125)+COUNTA('Validation Branch Tests'!$A$6:$A$65)+COUNTA('Evidence Mutation Tests'!$A$6:$A$40)+COUNTA('Session Flow Tests'!$A$6:$A$27) -> 237 | D6: Sheet | E6: Purpose | F6: Tests | G6: Expected field | H6: Editable fields
A7: Passed | B7: =COUNTIF('Ranking Stress Tests'!$AA$6:$AA$125,"Pass")+COUNTIF('Validation Branch Tests'!$N$6:$N$65,"Pass")+COUNTIF('Evidence Mutation Tests'!$M$6:$M$40,"Pass")+COUNTIF('Session Flow Tests'!$G$6:$G$27,"Pass") -> 0 | D7: Ranking Stress Tests | E7: All rank permutations | F7: 120 | G7: Expected Result | H7: Real Result, Status, Notes
A8: Failed | B8: =COUNTIF('Ranking Stress Tests'!$AA$6:$AA$125,"Fail")+COUNTIF('Validation Branch Tests'!$N$6:$N$65,"Fail")+COUNTIF('Evidence Mutation Tests'!$M$6:$M$40,"Fail")+COUNTIF('Session Flow Tests'!$G$6:$G$27,"Fail") -> 0 | D8: Validation Branch Tests | E8: Validate/skip branches | F8: 60 | G8: Expected Result | H8: Real Result, Status
A9: Blocked | B9: =COUNTIF('Ranking Stress Tests'!$AA$6:$AA$125,"Blocked")+COUNTIF('Validation Branch Tests'!$N$6:$N$65,"Blocked")+COUNTIF('Evidence Mutation Tests'!$M$6:$M$40,"Blocked")+COUNTIF('Session Flow Tests'!$G$6:$G$27,"Blocked") -> 0 | D9: Evidence Mutation Tests | E9: Metadata and text edits | F9: 35 | G9: Expected Result | H9: Real Result, Status
A10: Not Run | B10: =COUNTIF('Ranking Stress Tests'!$AA$6:$AA$125,"Not Run")+COUNTIF('Validation Branch Tests'!$N$6:$N$65,"Not Run")+COUNTIF('Evidence Mutation Tests'!$M$6:$M$40,"Not Run")+COUNTIF('Session Flow Tests'!$G$6:$G$27,"Not Run") -> 229 | D10: Session Flow Tests | E10: Randomness, UI, progress | F10: 22 | G10: Expected Result | H10: Real Result, Status, Notes
A13: Status | B13: Count
A14: Pass | B14: =B7 -> 0
A15: Fail | B15: =B8 -> 0
A16: Blocked | B16: =B9 -> 0
A17: Not Run | B17: =B10 -> 229
A18: Completion % | B18: =IF(B6=0,0,(B7+B8+B9)/B6) -> 0
A21: PASS CRITERION
A22: A row passes when the observed Unity behavior matches Expected Result, including answer type, scores, consequence, panel/button state, and session progress where applicable. Record defects with exact mission ID, rank order, path, and reproduction steps.

Sheet Test Guide
A1: CiteGuard VR Stress Test Evaluation
A3: Unity 6 (6000.3.21f1 LTS) | Meta Quest 3S target | Version 1 scripted RAG workflow
A5: HOW TO USE THIS WORKBOOK
A6: Step | B6: Action | C6: Instruction
A7: 1 | B7: Choose a test | C7: Start with Ranking Stress Tests for normal gameplay, then use the branch, mutation, and session sheets.
A8: 2 | B8: Identify evidence by role | C8: K1 is idealRank 1, K2 is idealRank 2, and D1/D2 are idealRank 0 distractors. Displayed Evidence A-D letters shuffle, so use the evidence ID/text.
A9: 3 | B9: Arrange the ranks | C9: Drag the four cards into Rank 1 through Rank 4 exactly as shown in the selected row.
A10: 4 | B10: Run the path | C10: Use Validate or Provide Answer/skip validation according to the test row.
A11: 5 | B11: Record behavior | C11: Enter what Unity actually showed in the yellow Real Result cell.
A12: 6 | B12: Compare | C12: Set Comparison Status to Pass, Fail, Blocked, or Not Run. Add reproducible details in Notes.
A14: EXPECTED SCORING RULES
A16: Rule | B16: Expected behavior | D16: Important limitation under test: Version 1 evaluates evidence metadata (idealRank), not the semantic meaning of the text. Changing evidence wording alone should not change the computed answer quality. The mutation sheet intentionally tests this behavior. Expected Result contains the specification. Real Result is intentionally blank for your Unity observation.
A17: Grounded | B17: K1 and K2 are both in Rank 1 or Rank 2.
A18: Partial | B18: Exactly one of K1 or K2 is in Rank 1 or Rank 2.
A19: Risky | B19: Neither K1 nor K2 is in Rank 1 or Rank 2.
A20: Retrieval Quality | B20: 100 / 50 / 0 for Grounded / Partial / Risky.
A21: Ranking Quality | B21: K1: max(0, 50 - |rank-1| x 15) plus K2: max(0, 50 - |rank-2| x 15).
A22: Final Trust | B22: Round((Retrieval + Ranking + Grounding + Citation + (100 - Hallucination Risk)) / 5).
A23: Send to LLM | B23: Disabled until all four ranking slots are filled.

Sheet Mission Evidence Map
A1: Mission & Evidence Map
A3: Stable evidence IDs are the source of truth; displayed A-D labels can change after shuffling.
A5: Mission ID | B5: Mission Title | C5: Crew Query | D5: K1 ID (idealRank 1) | E5: K1 Text | F5: K2 ID (idealRank 2) | G5: K2 Text | H5: D1 ID (idealRank 0) | I5: D1 Text | J5: D2 ID (idealRank 0) | K5: D2 Text | L5: Grounded Variants | M5: Partial Variants | N5: Risky Variants | O5: Success / Delayed / Failure | P5: Notes
A6: solar_shield | B6: Solar Shield Battery Check | C6: Can we activate the solar shield during low battery mode? | D6: shield_power_requirement | E6: The solar shield requires the battery level to be above 40%. | F6: low_battery_threshold | G6: Low battery mode begins when the battery level falls below 25%. | H6: oxygen_backup_power | I6: The oxygen system uses backup power during low battery mode. | J6: radiation_protection | K6: The solar shield protects the ship during radiation storms. | L6: 1) No. Low battery mode means the battery is below 25%, while the solar shield requires above 40%. The shield should remain offline. Supported by {KEY1} and {KEY2}. 2) The solar shield should not be activated. It requires more than 40% battery, but low battery mode begins below 25%. Supported by {KEY1} and {KEY2}. | M6: 1) Activation may be unsafe because the available evidence indicates a battery restriction, but the full threshold comparison is missing. 2) The ranked evidence provides only partial support, so the crew should not make the shield decision yet. | N6: 1) Yes. The solar shield can be activated because low battery mode uses backup power. 2) The shield should work during low battery mode because radiation protection is always required. | O6: SUCCESS: The shield remains offline. Battery power is preserved for essential systems. DELAYED: The crew pauses the decision while battery reserves continue to fall. FAILURE: The shield overloads the low-battery system and causes a shipwide power emergency.
A7: cargo_bay | B7: Cargo Bay Safety Check | C7: Can we open the exterior cargo bay while the ship is moving at cruise speed? | D7: cargo_speed_requirement | E7: Exterior cargo bay doors may open only when the ship speed is zero. | F7: cruise_speed_status | G7: Cruise mode keeps the ship moving above 5,000 kilometers per hour. | H7: cargo_contents | I7: The cargo bay stores repair drones and spare equipment. | J7: docking_clamps | K7: Docking clamps engage automatically near a space station. | L7: 1) No. The cargo bay doors may open only when ship speed is zero, while cruise mode keeps the ship moving above 5,000 kilometers per hour. Supported by {KEY1} and {KEY2}. 2) The exterior cargo bay must remain closed. Its doors require zero ship speed, which conflicts with the current cruise-speed condition. Supported by {KEY1} and {KEY2}. | M7: 1) Opening the cargo bay may be unsafe because the available evidence indicates a movement restriction, but the complete speed comparison is missing. 2) The ranked evidence is incomplete, so the crew should keep the cargo bay closed until the ship-speed requirement is confirmed. | N7: 1) Yes. The cargo bay can be opened because docking clamps will keep the ship stable. 2) The cargo bay may be opened during cruise because the repair drones can secure loose equipment. | O7: SUCCESS: The cargo bay remains sealed until the ship stops, preventing decompression and equipment loss. DELAYED: The crew pauses the cargo operation while confirming the ship-speed requirement. FAILURE: The cargo bay opens at cruise speed, causing rapid decompression and the loss of critical equipment.
A8: reactor_restart | B8: Reactor Coolant Check | C8: Should we restart the main reactor while the coolant temperature warning is active? | D8: reactor_restart_limit | E8: The reactor may restart only when coolant temperature is below 70 degrees Celsius. | F8: coolant_warning_threshold | G8: The coolant warning activates when temperature rises above 90 degrees Celsius. | H8: reactor_navigation_power | I8: The main reactor supplies power to navigation and propulsion. | J8: coolant_maintenance | K8: The coolant pumps passed inspection during the previous maintenance cycle. | L8: 1) No. The reactor may restart only below 70 degrees Celsius, while the warning means coolant temperature is above 90 degrees. Supported by {KEY1} and {KEY2}. 2) The reactor must remain offline. Its restart limit is below 70 degrees Celsius, but the active warning indicates a temperature above 90 degrees. Supported by {KEY1} and {KEY2}. | M8: 1) Restarting may be unsafe because the available evidence indicates a coolant restriction, but the complete temperature comparison is missing. 2) The selected evidence suggests delaying the restart, but it does not establish both the required and current temperature thresholds. | N8: 1) Yes. The reactor can be restarted because the coolant pumps passed their previous inspection. 2) The reactor should restart because navigation needs power, and the temperature warning can be monitored afterward. | O8: SUCCESS: The reactor remains offline while the coolant system lowers the temperature, preventing an overheat emergency. DELAYED: The crew postpones the restart while engineers verify the coolant temperature. FAILURE: The reactor restarts while overheated, triggering a reactor fire and an emergency power shutdown.
A9: eva_thrusters | B9: EVA Thruster Safety | C9: Can we fire the maneuvering thrusters while a technician is working outside the ship? | D9: thruster_eva_lockout | E9: Maneuvering thrusters must remain locked when EVA personnel are inside the thruster safety zone. | F9: technician_beacon | G9: The technician's suit beacon currently reports a position inside the thruster safety zone. | H9: spacesuit_oxygen | I9: The technician's spacesuit has 90 minutes of oxygen remaining. | J9: thruster_docking_use | K9: Maneuvering thrusters are normally used during docking operations. | L9: 1) No. Thrusters must remain locked when EVA personnel are inside the safety zone, and the technician's beacon confirms that condition. Supported by {KEY1} and {KEY2}. 2) The maneuvering thrusters should not be fired. The technician is currently inside the zone where EVA safety rules require a thruster lockout. Supported by {KEY1} and {KEY2}. | M9: 1) Firing the thrusters may be unsafe because the evidence indicates an EVA restriction, but the technician's current position is not fully confirmed. 2) The ranked evidence suggests keeping the thrusters locked, but additional location evidence is needed. | N9: 1) Yes. The technician has enough oxygen and can move away before the thrusters fire. 2) The thrusters can be fired because they are routinely used during docking and the suit beacon can track the technician. | O9: SUCCESS: The thrusters remain locked until the technician leaves the safety zone, preventing an EVA accident. DELAYED: The maneuver is postponed while the crew confirms the technician's location. FAILURE: The thruster blast pushes the technician away from the ship and damages critical spacesuit equipment.
A10: antenna_storm | B10: Antenna Debris Safety | C10: Can we extend the long-range antenna during the current micrometeor storm? | D10: antenna_debris_rule | E10: The long-range antenna must remain retracted whenever a debris alert is active. | F10: storm_debris_status | G10: The current micrometeor storm has triggered an active high-velocity debris alert. | H10: internal_communications | I10: Internal crew communication uses a separate short-range network. | J10: antenna_signal_strength | K10: The long-range antenna improves communication with distant stations. | L10: 1) No. The antenna must remain retracted during an active debris alert, and the current storm has triggered that alert. Supported by {KEY1} and {KEY2}. 2) The long-range antenna should not be extended. The micrometeor storm creates the exact debris condition that requires it to remain retracted. Supported by {KEY1} and {KEY2}. | M10: 1) Extending the antenna may be unsafe because the available evidence indicates a debris restriction, but the current alert status is not fully confirmed. 2) The ranked evidence suggests keeping the antenna retracted, but the storm condition requires additional confirmation. | N10: 1) Yes. The antenna should be extended because communication with distant stations is especially important during a storm. 2) The antenna can be extended because internal communications use a separate network if the long-range system is damaged. | O10: SUCCESS: The antenna remains protected until the storm passes, preserving long-range communications. DELAYED: The crew postpones external communication while checking the debris alert. FAILURE: High-velocity debris strikes the extended antenna, destroying the ship's long-range communication system.

Sheet Ranking Stress Tests
A1: Ranking Stress Tests
A3: All 120 possible rank orders. Follow the stable K1/K2/D1/D2 roles, then compare Unity with Expected Result.
A5: Test ID | B5: Mission ID | C5: Mission Title | D5: Crew Query | E5: Rank 1 Role | F5: Rank 1 Evidence | G5: Rank 2 Role | H5: Rank 2 Evidence | I5: Rank 3 Role | J5: Rank 3 Evidence | K5: Rank 4 Role | L5: Rank 4 Evidence | M5: K1 Rank | N5: K2 Rank | O5: Expected Answer Type | P5: Expected Retrieval % | Q5: Expected Ranking % | R5: Expected Grounding % | S5: Expected Citation % | T5: Expected Hallucination Risk % | U5: Expected Trust % | V5: Correct Validation Choice | W5: Expected Validated Outcome | X5: Expected Skipped Outcome | Y5: Expected Result | Z5: Real Result | AA5: Comparison Status | AB5: Notes
A6: R-solar_shield-01 | B6: solar_shield | C6: Solar Shield Battery Check | D6: Can we activate the solar shield during low battery mode? | E6: K1 | F6: shield_power_requirement: The solar shield requires the battery level to be above 40%. | G6: K2 | H6: low_battery_threshold: Low battery mode begins when the battery level falls below 25%. | I6: D1 | J6: oxygen_backup_power: The oxygen system uses backup power during low battery mode. | K6: D2 | L6: radiation_protection: The solar shield protects the ship during radiation storms. | M6: =IF(E6="K1",1,IF(G6="K1",2,IF(I6="K1",3,4))) -> 1 | N6: =IF(E6="K2",1,IF(G6="K2",2,IF(I6="K2",3,4))) -> 2 | O6: =IF(AND(M6<=2,N6<=2),"Grounded",IF(OR(M6<=2,N6<=2),"Partial","Risky")) -> Grounded | P6: =IF(O6="Grounded",100,IF(O6="Partial",50,0)) -> 100 | Q6: =MAX(0,50-ABS(M6-1)*15)+MAX(0,50-ABS(N6-2)*15) -> 100 | R6: =IF(O6="Grounded",100,IF(O6="Partial",60,10)) -> 100 | S6: =IF(O6="Grounded",100,IF(O6="Partial",50,0)) -> 100 | T6: =IF(O6="Grounded",0,IF(O6="Partial",40,90)) -> 0 | U6: =ROUND((P6+Q6+R6+S6+(100-T6))/5,0) -> 100 | V6: =O6 -> Grounded | W6: =IF(O6="Grounded","MISSION SUCCESS: The shield remains offline. Battery power is preserved for essential systems.",IF(O6="Partial","MISSION PROTECTED: Response held for more evidence; Try New Mission.","RISK BLOCKED: Unsupported action prevented; Try New Mission.")) -> MISSION SUCCESS: The shield remains offline. Battery power is preserved for essential systems. | X6: =IF(O6="Grounded","MISSION SUCCESS + PROCESS WARNING; trust 70. The shield remains offline. Battery power is preserved for essential systems.",IF(O6="Partial","MISSION DELAYED; trust 35. The crew pauses the decision while battery reserves continue to fall.","GAME OVER; trust 5. The shield overloads the low-battery system and causes a shipwide power emergency.")) -> MISSION SUCCESS + PROCESS WARNING; trust 70. The shield remains offline. Battery power is preserved for essential systems. | Y6: =O6&" answer | Retrieval "&P6&"% | Ranking "&Q6&"% | Grounding "&R6&"% | Citation "&S6&"% | Hallucination Risk "&T6&"% | Trust "&U6&"%" -> Grounded answer | Retrieval 100% | Ranking 100% | Grounding 100% | Citation 100% | Hallucination Risk 0% | Trust 100% | Z6: Success | AA6: Run
A7: R-solar_shield-02 | B7: solar_shield | C7: Solar Shield Battery Check | D7: Can we activate the solar shield during low battery mode? | E7: K1 | F7: shield_power_requirement: The solar shield requires the battery level to be above 40%. | G7: K2 | H7: low_battery_threshold: Low battery mode begins when the battery level falls below 25%. | I7: D2 | J7: radiation_protection: The solar shield protects the ship during radiation storms. | K7: D1 | L7: oxygen_backup_power: The oxygen system uses backup power during low battery mode. | M7: =IF(E7="K1",1,IF(G7="K1",2,IF(I7="K1",3,4))) -> 1 | N7: =IF(E7="K2",1,IF(G7="K2",2,IF(I7="K2",3,4))) -> 2 | O7: =IF(AND(M7<=2,N7<=2),"Grounded",IF(OR(M7<=2,N7<=2),"Partial","Risky")) -> Grounded | P7: =IF(O7="Grounded",100,IF(O7="Partial",50,0)) -> 100 | Q7: =MAX(0,50-ABS(M7-1)*15)+MAX(0,50-ABS(N7-2)*15) -> 100 | R7: =IF(O7="Grounded",100,IF(O7="Partial",60,10)) -> 100 | S7: =IF(O7="Grounded",100,IF(O7="Partial",50,0)) -> 100 | T7: =IF(O7="Grounded",0,IF(O7="Partial",40,90)) -> 0 | U7: =ROUND((P7+Q7+R7+S7+(100-T7))/5,0) -> 100 | V7: =O7 -> Grounded | W7: =IF(O7="Grounded","MISSION SUCCESS: The shield remains offline. Battery power is preserved for essential systems.",IF(O7="Partial","MISSION PROTECTED: Response held for more evidence; Try New Mission.","RISK BLOCKED: Unsupported action prevented; Try New Mission.")) -> MISSION SUCCESS: The shield remains offline. Battery power is preserved for essential systems. | X7: =IF(O7="Grounded","MISSION SUCCESS + PROCESS WARNING; trust 70. The shield remains offline. Battery power is preserved for essential systems.",IF(O7="Partial","MISSION DELAYED; trust 35. The crew pauses the decision while battery reserves continue to fall.","GAME OVER; trust 5. The shield overloads the low-battery system and causes a shipwide power emergency.")) -> MISSION SUCCESS + PROCESS WARNING; trust 70. The shield remains offline. Battery power is preserved for essential systems. | Y7: =O7&" answer | Retrieval "&P7&"% | Ranking "&Q7&"% | Grounding "&R7&"% | Citation "&S7&"% | Hallucination Risk "&T7&"% | Trust "&U7&"%" -> Grounded answer | Retrieval 100% | Ranking 100% | Grounding 100% | Citation 100% | Hallucination Risk 0% | Trust 100% | Z7: Success | AA7: Run
A8: R-solar_shield-03 | B8: solar_shield | C8: Solar Shield Battery Check | D8: Can we activate the solar shield during low battery mode? | E8: K1 | F8: shield_power_requirement: The solar shield requires the battery level to be above 40%. | G8: D1 | H8: oxygen_backup_power: The oxygen system uses backup power during low battery mode. | I8: K2 | J8: low_battery_threshold: Low battery mode begins when the battery level falls below 25%. | K8: D2 | L8: radiation_protection: The solar shield protects the ship during radiation storms. | M8: =IF(E8="K1",1,IF(G8="K1",2,IF(I8="K1",3,4))) -> 1 | N8: =IF(E8="K2",1,IF(G8="K2",2,IF(I8="K2",3,4))) -> 3 | O8: =IF(AND(M8<=2,N8<=2),"Grounded",IF(OR(M8<=2,N8<=2),"Partial","Risky")) -> Partial | P8: =IF(O8="Grounded",100,IF(O8="Partial",50,0)) -> 50 | Q8: =MAX(0,50-ABS(M8-1)*15)+MAX(0,50-ABS(N8-2)*15) -> 85 | R8: =IF(O8="Grounded",100,IF(O8="Partial",60,10)) -> 60 | S8: =IF(O8="Grounded",100,IF(O8="Partial",50,0)) -> 50 | T8: =IF(O8="Grounded",0,IF(O8="Partial",40,90)) -> 40 | U8: =ROUND((P8+Q8+R8+S8+(100-T8))/5,0) -> 61 | V8: =O8 -> Partial | W8: =IF(O8="Grounded","MISSION SUCCESS: The shield remains offline. Battery power is preserved for essential systems.",IF(O8="Partial","MISSION PROTECTED: Response held for more evidence; Try New Mission.","RISK BLOCKED: Unsupported action prevented; Try New Mission.")) -> MISSION PROTECTED: Response held for more evidence; Try New Mission. | X8: =IF(O8="Grounded","MISSION SUCCESS + PROCESS WARNING; trust 70. The shield remains offline. Battery power is preserved for essential systems.",IF(O8="Partial","MISSION DELAYED; trust 35. The crew pauses the decision while battery reserves continue to fall.","GAME OVER; trust 5. The shield overloads the low-battery system and causes a shipwide power emergency.")) -> MISSION DELAYED; trust 35. The crew pauses the decision while battery reserves continue to fall. | Y8: =O8&" answer | Retrieval "&P8&"% | Ranking "&Q8&"% | Grounding "&R8&"% | Citation "&S8&"% | Hallucination Risk "&T8&"% | Trust "&U8&"%" -> Partial answer | Retrieval 50% | Ranking 85% | Grounding 60% | Citation 50% | Hallucination Risk 40% | Trust 61% | AA8: Not Run
A9: R-solar_shield-04 | B9: solar_shield | C9: Solar Shield Battery Check | D9: Can we activate the solar shield during low battery mode? | E9: K1 | F9: shield_power_requirement: The solar shield requires the battery level to be above 40%. | G9: D1 | H9: oxygen_backup_power: The oxygen system uses backup power during low battery mode. | I9: D2 | J9: radiation_protection: The solar shield protects the ship during radiation storms. | K9: K2 | L9: low_battery_threshold: Low battery mode begins when the battery level falls below 25%. | M9: =IF(E9="K1",1,IF(G9="K1",2,IF(I9="K1",3,4))) -> 1 | N9: =IF(E9="K2",1,IF(G9="K2",2,IF(I9="K2",3,4))) -> 4 | O9: =IF(AND(M9<=2,N9<=2),"Grounded",IF(OR(M9<=2,N9<=2),"Partial","Risky")) -> Partial | P9: =IF(O9="Grounded",100,IF(O9="Partial",50,0)) -> 50 | Q9: =MAX(0,50-ABS(M9-1)*15)+MAX(0,50-ABS(N9-2)*15) -> 70 | R9: =IF(O9="Grounded",100,IF(O9="Partial",60,10)) -> 60 | S9: =IF(O9="Grounded",100,IF(O9="Partial",50,0)) -> 50 | T9: =IF(O9="Grounded",0,IF(O9="Partial",40,90)) -> 40 | U9: =ROUND((P9+Q9+R9+S9+(100-T9))/5,0) -> 58 | V9: =O9 -> Partial | W9: =IF(O9="Grounded","MISSION SUCCESS: The shield remains offline. Battery power is preserved for essential systems.",IF(O9="Partial","MISSION PROTECTED: Response held for more evidence; Try New Mission.","RISK BLOCKED: Unsupported action prevented; Try New Mission.")) -> MISSION PROTECTED: Response held for more evidence; Try New Mission. | X9: =IF(O9="Grounded","MISSION SUCCESS + PROCESS WARNING; trust 70. The shield remains offline. Battery power is preserved for essential systems.",IF(O9="Partial","MISSION DELAYED; trust 35. The crew pauses the decision while battery reserves continue to fall.","GAME OVER; trust 5. The shield overloads the low-battery system and causes a shipwide power emergency.")) -> MISSION DELAYED; trust 35. The crew pauses the decision while battery reserves continue to fall. | Y9: =O9&" answer | Retrieval "&P9&"% | Ranking "&Q9&"% | Grounding "&R9&"% | Citation "&S9&"% | Hallucination Risk "&T9&"% | Trust "&U9&"%" -> Partial answer | Retrieval 50% | Ranking 70% | Grounding 60% | Citation 50% | Hallucination Risk 40% | Trust 58% | AA9: Not Run
A10: R-solar_shield-05 | B10: solar_shield | C10: Solar Shield Battery Check | D10: Can we activate the solar shield during low battery mode? | E10: K1 | F10: shield_power_requirement: The solar shield requires the battery level to be above 40%. | G10: D2 | H10: radiation_protection: The solar shield protects the ship during radiation storms. | I10: K2 | J10: low_battery_threshold: Low battery mode begins when the battery level falls below 25%. | K10: D1 | L10: oxygen_backup_power: The oxygen system uses backup power during low battery mode. | M10: =IF(E10="K1",1,IF(G10="K1",2,IF(I10="K1",3,4))) -> 1 | N10: =IF(E10="K2",1,IF(G10="K2",2,IF(I10="K2",3,4))) -> 3 | O10: =IF(AND(M10<=2,N10<=2),"Grounded",IF(OR(M10<=2,N10<=2),"Partial","Risky")) -> Partial | P10: =IF(O10="Grounded",100,IF(O10="Partial",50,0)) -> 50 | Q10: =MAX(0,50-ABS(M10-1)*15)+MAX(0,50-ABS(N10-2)*15) -> 85 | R10: =IF(O10="Grounded",100,IF(O10="Partial",60,10)) -> 60 | S10: =IF(O10="Grounded",100,IF(O10="Partial",50,0)) -> 50 | T10: =IF(O10="Grounded",0,IF(O10="Partial",40,90)) -> 40 | U10: =ROUND((P10+Q10+R10+S10+(100-T10))/5,0) -> 61 | V10: =O10 -> Partial | W10: =IF(O10="Grounded","MISSION SUCCESS: The shield remains offline. Battery power is preserved for essential systems.",IF(O10="Partial","MISSION PROTECTED: Response held for more evidence; Try New Mission.","RISK BLOCKED: Unsupported action prevented; Try New Mission.")) -> MISSION PROTECTED: Response held for more evidence; Try New Mission. | X10: =IF(O10="Grounded","MISSION SUCCESS + PROCESS WARNING; trust 70. The shield remains offline. Battery power is preserved for essential systems.",IF(O10="Partial","MISSION DELAYED; trust 35. The crew pauses the decision while battery reserves continue to fall.","GAME OVER; trust 5. The shield overloads the low-battery system and causes a shipwide power emergency.")) -> MISSION DELAYED; trust 35. The crew pauses the decision while battery reserves continue to fall. | Y10: =O10&" answer | Retrieval "&P10&"% | Ranking "&Q10&"% | Grounding "&R10&"% | Citation "&S10&"% | Hallucination Risk "&T10&"% | Trust "&U10&"%" -> Partial answer | Retrieval 50% | Ranking 85% | Grounding 60% | Citation 50% | Hallucination Risk 40% | Trust 61% | AA10: Not Run
A11: R-solar_shield-06 | B11: solar_shield | C11: Solar Shield Battery Check | D11: Can we activate the solar shield during low battery mode? | E11: K1 | F11: shield_power_requirement: The solar shield requires the battery level to be above 40%. | G11: D2 | H11: radiation_protection: The solar shield protects the ship during radiation storms. | I11: D1 | J11: oxygen_backup_power: The oxygen system uses backup power during low battery mode. | K11: K2 | L11: low_battery_threshold: Low battery mode begins when the battery level falls below 25%. | M11: =IF(E11="K1",1,IF(G11="K1",2,IF(I11="K1",3,4))) -> 1 | N11: =IF(E11="K2",1,IF(G11="K2",2,IF(I11="K2",3,4))) -> 4 | O11: =IF(AND(M11<=2,N11<=2),"Grounded",IF(OR(M11<=2,N11<=2),"Partial","Risky")) -> Partial | P11: =IF(O11="Grounded",100,IF(O11="Partial",50,0)) -> 50 | Q11: =MAX(0,50-ABS(M11-1)*15)+MAX(0,50-ABS(N11-2)*15) -> 70 | R11: =IF(O11="Grounded",100,IF(O11="Partial",60,10)) -> 60 | S11: =IF(O11="Grounded",100,IF(O11="Partial",50,0)) -> 50 | T11: =IF(O11="Grounded",0,IF(O11="Partial",40,90)) -> 40 | U11: =ROUND((P11+Q11+R11+S11+(100-T11))/5,0) -> 58 | V11: =O11 -> Partial | W11: =IF(O11="Grounded","MISSION SUCCESS: The shield remains offline. Battery power is preserved for essential systems.",IF(O11="Partial","MISSION PROTECTED: Response held for more evidence; Try New Mission.","RISK BLOCKED: Unsupported action prevented; Try New Mission.")) -> MISSION PROTECTED: Response held for more evidence; Try New Mission. | X11: =IF(O11="Grounded","MISSION SUCCESS + PROCESS WARNING; trust 70. The shield remains offline. Battery power is preserved for essential systems.",IF(O11="Partial","MISSION DELAYED; trust 35. The crew pauses the decision while battery reserves continue to fall.","GAME OVER; trust 5. The shield overloads the low-battery system and causes a shipwide power emergency.")) -> MISSION DELAYED; trust 35. The crew pauses the decision while battery reserves continue to fall. | Y11: =O11&" answer | Retrieval "&P11&"% | Ranking "&Q11&"% | Grounding "&R11&"% | Citation "&S11&"% | Hallucination Risk "&T11&"% | Trust "&U11&"%" -> Partial answer | Retrieval 50% | Ranking 70% | Grounding 60% | Citation 50% | Hallucination Risk 40% | Trust 58% | AA11: Not Run
A12: R-solar_shield-07 | B12: solar_shield | C12: Solar Shield Battery Check | D12: Can we activate the solar shield during low battery mode? | E12: K2 | F12: low_battery_threshold: Low battery mode begins when the battery level falls below 25%. | G12: K1 | H12: shield_power_requirement: The solar shield requires the battery level to be above 40%. | I12: D1 | J12: oxygen_backup_power: The oxygen system uses backup power during low battery mode. | K12: D2 | L12: radiation_protection: The solar shield protects the ship during radiation storms. | M12: =IF(E12="K1",1,IF(G12="K1",2,IF(I12="K1",3,4))) -> 2 | N12: =IF(E12="K2",1,IF(G12="K2",2,IF(I12="K2",3,4))) -> 1 | O12: =IF(AND(M12<=2,N12<=2),"Grounded",IF(OR(M12<=2,N12<=2),"Partial","Risky")) -> Grounded | P12: =IF(O12="Grounded",100,IF(O12="Partial",50,0)) -> 100 | Q12: =MAX(0,50-ABS(M12-1)*15)+MAX(0,50-ABS(N12-2)*15) -> 70 | R12: =IF(O12="Grounded",100,IF(O12="Partial",60,10)) -> 100 | S12: =IF(O12="Grounded",100,IF(O12="Partial",50,0)) -> 100 | T12: =IF(O12="Grounded",0,IF(O12="Partial",40,90)) -> 0 | U12: =ROUND((P12+Q12+R12+S12+(100-T12))/5,0) -> 94 | V12: =O12 -> Grounded | W12: =IF(O12="Grounded","MISSION SUCCESS: The shield remains offline. Battery power is preserved for essential systems.",IF(O12="Partial","MISSION PROTECTED: Response held for more evidence; Try New Mission.","RISK BLOCKED: Unsupported action prevented; Try New Mission.")) -> MISSION SUCCESS: The shield remains offline. Battery power is preserved for essential systems. | X12: =IF(O12="Grounded","MISSION SUCCESS + PROCESS WARNING; trust 70. The shield remains offline. Battery power is preserved for essential systems.",IF(O12="Partial","MISSION DELAYED; trust 35. The crew pauses the decision while battery reserves continue to fall.","GAME OVER; trust 5. The shield overloads the low-battery system and causes a shipwide power emergency.")) -> MISSION SUCCESS + PROCESS WARNING; trust 70. The shield remains offline. Battery power is preserved for essential systems. | Y12: =O12&" answer | Retrieval "&P12&"% | Ranking "&Q12&"% | Grounding "&R12&"% | Citation "&S12&"% | Hallucination Risk "&T12&"% | Trust "&U12&"%" -> Grounded answer | Retrieval 100% | Ranking 70% | Grounding 100% | Citation 100% | Hallucination Risk 0% | Trust 94% | AA12: Not Run
A13: R-solar_shield-08 | B13: solar_shield | C13: Solar Shield Battery Check | D13: Can we activate the solar shield during low battery mode? | E13: K2 | F13: low_battery_threshold: Low battery mode begins when the battery level falls below 25%. | G13: K1 | H13: shield_power_requirement: The solar shield requires the battery level to be above 40%. | I13: D2 | J13: radiation_protection: The solar shield protects the ship during radiation storms. | K13: D1 | L13: oxygen_backup_power: The oxygen system uses backup power during low battery mode. | M13: =IF(E13="K1",1,IF(G13="K1",2,IF(I13="K1",3,4))) -> 2 | N13: =IF(E13="K2",1,IF(G13="K2",2,IF(I13="K2",3,4))) -> 1 | O13: =IF(AND(M13<=2,N13<=2),"Grounded",IF(OR(M13<=2,N13<=2),"Partial","Risky")) -> Grounded | P13: =IF(O13="Grounded",100,IF(O13="Partial",50,0)) -> 100 | Q13: =MAX(0,50-ABS(M13-1)*15)+MAX(0,50-ABS(N13-2)*15) -> 70 | R13: =IF(O13="Grounded",100,IF(O13="Partial",60,10)) -> 100 | S13: =IF(O13="Grounded",100,IF(O13="Partial",50,0)) -> 100 | T13: =IF(O13="Grounded",0,IF(O13="Partial",40,90)) -> 0 | U13: =ROUND((P13+Q13+R13+S13+(100-T13))/5,0) -> 94 | V13: =O13 -> Grounded | W13: =IF(O13="Grounded","MISSION SUCCESS: The shield remains offline. Battery power is preserved for essential systems.",IF(O13="Partial","MISSION PROTECTED: Response held for more evidence; Try New Mission.","RISK BLOCKED: Unsupported action prevented; Try New Mission.")) -> MISSION SUCCESS: The shield remains offline. Battery power is preserved for essential systems. | X13: =IF(O13="Grounded","MISSION SUCCESS + PROCESS WARNING; trust 70. The shield remains offline. Battery power is preserved for essential systems.",IF(O13="Partial","MISSION DELAYED; trust 35. The crew pauses the decision while battery reserves continue to fall.","GAME OVER; trust 5. The shield overloads the low-battery system and causes a shipwide power emergency.")) -> MISSION SUCCESS + PROCESS WARNING; trust 70. The shield remains offline. Battery power is preserved for essential systems. | Y13: =O13&" answer | Retrieval "&P13&"% | Ranking "&Q13&"% | Grounding "&R13&"% | Citation "&S13&"% | Hallucination Risk "&T13&"% | Trust "&U13&"%" -> Grounded answer | Retrieval 100% | Ranking 70% | Grounding 100% | Citation 100% | Hallucination Risk 0% | Trust 94% | AA13: Not Run
A14: R-solar_shield-09 | B14: solar_shield | C14: Solar Shield Battery Check | D14: Can we activate the solar shield during low battery mode? | E14: K2 | F14: low_battery_threshold: Low battery mode begins when the battery level falls below 25%. | G14: D1 | H14: oxygen_backup_power: The oxygen system uses backup power during low battery mode. | I14: K1 | J14: shield_power_requirement: The solar shield requires the battery level to be above 40%. | K14: D2 | L14: radiation_protection: The solar shield protects the ship during radiation storms. | M14: =IF(E14="K1",1,IF(G14="K1",2,IF(I14="K1",3,4))) -> 3 | N14: =IF(E14="K2",1,IF(G14="K2",2,IF(I14="K2",3,4))) -> 1 | O14: =IF(AND(M14<=2,N14<=2),"Grounded",IF(OR(M14<=2,N14<=2),"Partial","Risky")) -> Partial | P14: =IF(O14="Grounded",100,IF(O14="Partial",50,0)) -> 50 | Q14: =MAX(0,50-ABS(M14-1)*15)+MAX(0,50-ABS(N14-2)*15) -> 55 | R14: =IF(O14="Grounded",100,IF(O14="Partial",60,10)) -> 60 | S14: =IF(O14="Grounded",100,IF(O14="Partial",50,0)) -> 50 | T14: =IF(O14="Grounded",0,IF(O14="Partial",40,90)) -> 40 | U14: =ROUND((P14+Q14+R14+S14+(100-T14))/5,0) -> 55 | V14: =O14 -> Partial | W14: =IF(O14="Grounded","MISSION SUCCESS: The shield remains offline. Battery power is preserved for essential systems.",IF(O14="Partial","MISSION PROTECTED: Response held for more evidence; Try New Mission.","RISK BLOCKED: Unsupported action prevented; Try New Mission.")) -> MISSION PROTECTED: Response held for more evidence; Try New Mission. | X14: =IF(O14="Grounded","MISSION SUCCESS + PROCESS WARNING; trust 70. The shield remains offline. Battery power is preserved for essential systems.",IF(O14="Partial","MISSION DELAYED; trust 35. The crew pauses the decision while battery reserves continue to fall.","GAME OVER; trust 5. The shield overloads the low-battery system and causes a shipwide power emergency.")) -> MISSION DELAYED; trust 35. The crew pauses the decision while battery reserves continue to fall. | Y14: =O14&" answer | Retrieval "&P14&"% | Ranking "&Q14&"% | Grounding "&R14&"% | Citation "&S14&"% | Hallucination Risk "&T14&"% | Trust "&U14&"%" -> Partial answer | Retrieval 50% | Ranking 55% | Grounding 60% | Citation 50% | Hallucination Risk 40% | Trust 55% | AA14: Not Run
A15: R-solar_shield-10 | B15: solar_shield | C15: Solar Shield Battery Check | D15: Can we activate the solar shield during low battery mode? | E15: K2 | F15: low_battery_threshold: Low battery mode begins when the battery level falls below 25%. | G15: D1 | H15: oxygen_backup_power: The oxygen system uses backup power during low battery mode. | I15: D2 | J15: radiation_protection: The solar shield protects the ship during radiation storms. | K15: K1 | L15: shield_power_requirement: The solar shield requires the battery level to be above 40%. | M15: =IF(E15="K1",1,IF(G15="K1",2,IF(I15="K1",3,4))) -> 4 | N15: =IF(E15="K2",1,IF(G15="K2",2,IF(I15="K2",3,4))) -> 1 | O15: =IF(AND(M15<=2,N15<=2),"Grounded",IF(OR(M15<=2,N15<=2),"Partial","Risky")) -> Partial | P15: =IF(O15="Grounded",100,IF(O15="Partial",50,0)) -> 50 | Q15: =MAX(0,50-ABS(M15-1)*15)+MAX(0,50-ABS(N15-2)*15) -> 40 | R15: =IF(O15="Grounded",100,IF(O15="Partial",60,10)) -> 60 | S15: =IF(O15="Grounded",100,IF(O15="Partial",50,0)) -> 50 | T15: =IF(O15="Grounded",0,IF(O15="Partial",40,90)) -> 40 | U15: =ROUND((P15+Q15+R15+S15+(100-T15))/5,0) -> 52 | V15: =O15 -> Partial | W15: =IF(O15="Grounded","MISSION SUCCESS: The shield remains offline. Battery power is preserved for essential systems.",IF(O15="Partial","MISSION PROTECTED: Response held for more evidence; Try New Mission.","RISK BLOCKED: Unsupported action prevented; Try New Mission.")) -> MISSION PROTECTED: Response held for more evidence; Try New Mission. | X15: =IF(O15="Grounded","MISSION SUCCESS + PROCESS WARNING; trust 70. The shield remains offline. Battery power is preserved for essential systems.",IF(O15="Partial","MISSION DELAYED; trust 35. The crew pauses the decision while battery reserves continue to fall.","GAME OVER; trust 5. The shield overloads the low-battery system and causes a shipwide power emergency.")) -> MISSION DELAYED; trust 35. The crew pauses the decision while battery reserves continue to fall. | Y15: =O15&" answer | Retrieval "&P15&"% | Ranking "&Q15&"% | Grounding "&R15&"% | Citation "&S15&"% | Hallucination Risk "&T15&"% | Trust "&U15&"%" -> Partial answer | Retrieval 50% | Ranking 40% | Grounding 60% | Citation 50% | Hallucination Risk 40% | Trust 52% | AA15: Not Run
A16: R-solar_shield-11 | B16: solar_shield | C16: Solar Shield Battery Check | D16: Can we activate the solar shield during low battery mode? | E16: K2 | F16: low_battery_threshold: Low battery mode begins when the battery level falls below 25%. | G16: D2 | H16: radiation_protection: The solar shield protects the ship during radiation storms. | I16: K1 | J16: shield_power_requirement: The solar shield requires the battery level to be above 40%. | K16: D1 | L16: oxygen_backup_power: The oxygen system uses backup power during low battery mode. | M16: =IF(E16="K1",1,IF(G16="K1",2,IF(I16="K1",3,4))) -> 3 | N16: =IF(E16="K2",1,IF(G16="K2",2,IF(I16="K2",3,4))) -> 1 | O16: =IF(AND(M16<=2,N16<=2),"Grounded",IF(OR(M16<=2,N16<=2),"Partial","Risky")) -> Partial | P16: =IF(O16="Grounded",100,IF(O16="Partial",50,0)) -> 50 | Q16: =MAX(0,50-ABS(M16-1)*15)+MAX(0,50-ABS(N16-2)*15) -> 55 | R16: =IF(O16="Grounded",100,IF(O16="Partial",60,10)) -> 60 | S16: =IF(O16="Grounded",100,IF(O16="Partial",50,0)) -> 50 | T16: =IF(O16="Grounded",0,IF(O16="Partial",40,90)) -> 40 | U16: =ROUND((P16+Q16+R16+S16+(100-T16))/5,0) -> 55 | V16: =O16 -> Partial | W16: =IF(O16="Grounded","MISSION SUCCESS: The shield remains offline. Battery power is preserved for essential systems.",IF(O16="Partial","MISSION PROTECTED: Response held for more evidence; Try New Mission.","RISK BLOCKED: Unsupported action prevented; Try New Mission.")) -> MISSION PROTECTED: Response held for more evidence; Try New Mission. | X16: =IF(O16="Grounded","MISSION SUCCESS + PROCESS WARNING; trust 70. The shield remains offline. Battery power is preserved for essential systems.",IF(O16="Partial","MISSION DELAYED; trust 35. The crew pauses the decision while battery reserves continue to fall.","GAME OVER; trust 5. The shield overloads the low-battery system and causes a shipwide power emergency.")) -> MISSION DELAYED; trust 35. The crew pauses the decision while battery reserves continue to fall. | Y16: =O16&" answer | Retrieval "&P16&"% | Ranking "&Q16&"% | Grounding "&R16&"% | Citation "&S16&"% | Hallucination Risk "&T16&"% | Trust "&U16&"%" -> Partial answer | Retrieval 50% | Ranking 55% | Grounding 60% | Citation 50% | Hallucination Risk 40% | Trust 55% | AA16: Not Run
A17: R-solar_shield-12 | B17: solar_shield | C17: Solar Shield Battery Check | D17: Can we activate the solar shield during low battery mode? | E17: K2 | F17: low_battery_threshold: Low battery mode begins when the battery level falls below 25%. | G17: D2 | H17: radiation_protection: The solar shield protects the ship during radiation storms. | I17: D1 | J17: oxygen_backup_power: The oxygen system uses backup power during low battery mode. | K17: K1 | L17: shield_power_requirement: The solar shield requires the battery level to be above 40%. | M17: =IF(E17="K1",1,IF(G17="K1",2,IF(I17="K1",3,4))) -> 4 | N17: =IF(E17="K2",1,IF(G17="K2",2,IF(I17="K2",3,4))) -> 1 | O17: =IF(AND(M17<=2,N17<=2),"Grounded",IF(OR(M17<=2,N17<=2),"Partial","Risky")) -> Partial | P17: =IF(O17="Grounded",100,IF(O17="Partial",50,0)) -> 50 | Q17: =MAX(0,50-ABS(M17-1)*15)+MAX(0,50-ABS(N17-2)*15) -> 40 | R17: =IF(O17="Grounded",100,IF(O17="Partial",60,10)) -> 60 | S17: =IF(O17="Grounded",100,IF(O17="Partial",50,0)) -> 50 | T17: =IF(O17="Grounded",0,IF(O17="Partial",40,90)) -> 40 | U17: =ROUND((P17+Q17+R17+S17+(100-T17))/5,0) -> 52 | V17: =O17 -> Partial | W17: =IF(O17="Grounded","MISSION SUCCESS: The shield remains offline. Battery power is preserved for essential systems.",IF(O17="Partial","MISSION PROTECTED: Response held for more evidence; Try New Mission.","RISK BLOCKED: Unsupported action prevented; Try New Mission.")) -> MISSION PROTECTED: Response held for more evidence; Try New Mission. | X17: =IF(O17="Grounded","MISSION SUCCESS + PROCESS WARNING; trust 70. The shield remains offline. Battery power is preserved for essential systems.",IF(O17="Partial","MISSION DELAYED; trust 35. The crew pauses the decision while battery reserves continue to fall.","GAME OVER; trust 5. The shield overloads the low-battery system and causes a shipwide power emergency.")) -> MISSION DELAYED; trust 35. The crew pauses the decision while battery reserves continue to fall. | Y17: =O17&" answer | Retrieval "&P17&"% | Ranking "&Q17&"% | Grounding "&R17&"% | Citation "&S17&"% | Hallucination Risk "&T17&"% | Trust "&U17&"%" -> Partial answer | Retrieval 50% | Ranking 40% | Grounding 60% | Citation 50% | Hallucination Risk 40% | Trust 52% | AA17: Not Run
A18: R-solar_shield-13 | B18: solar_shield | C18: Solar Shield Battery Check | D18: Can we activate the solar shield during low battery mode? | E18: D1 | F18: oxygen_backup_power: The oxygen system uses backup power during low battery mode. | G18: K1 | H18: shield_power_requirement: The solar shield requires the battery level to be above 40%. | I18: K2 | J18: low_battery_threshold: Low battery mode begins when the battery level falls below 25%. | K18: D2 | L18: radiation_protection: The solar shield protects the ship during radiation storms. | M18: =IF(E18="K1",1,IF(G18="K1",2,IF(I18="K1",3,4))) -> 2 | N18: =IF(E18="K2",1,IF(G18="K2",2,IF(I18="K2",3,4))) -> 3 | O18: =IF(AND(M18<=2,N18<=2),"Grounded",IF(OR(M18<=2,N18<=2),"Partial","Risky")) -> Partial | P18: =IF(O18="Grounded",100,IF(O18="Partial",50,0)) -> 50 | Q18: =MAX(0,50-ABS(M18-1)*15)+MAX(0,50-ABS(N18-2)*15) -> 70 | R18: =IF(O18="Grounded",100,IF(O18="Partial",60,10)) -> 60 | S18: =IF(O18="Grounded",100,IF(O18="Partial",50,0)) -> 50 | T18: =IF(O18="Grounded",0,IF(O18="Partial",40,90)) -> 40 | U18: =ROUND((P18+Q18+R18+S18+(100-T18))/5,0) -> 58 | V18: =O18 -> Partial | W18: =IF(O18="Grounded","MISSION SUCCESS: The shield remains offline. Battery power is preserved for essential systems.",IF(O18="Partial","MISSION PROTECTED: Response held for more evidence; Try New Mission.","RISK BLOCKED: Unsupported action prevented; Try New Mission.")) -> MISSION PROTECTED: Response held for more evidence; Try New Mission. | X18: =IF(O18="Grounded","MISSION SUCCESS + PROCESS WARNING; trust 70. The shield remains offline. Battery power is preserved for essential systems.",IF(O18="Partial","MISSION DELAYED; trust 35. The crew pauses the decision while battery reserves continue to fall.","GAME OVER; trust 5. The shield overloads the low-battery system and causes a shipwide power emergency.")) -> MISSION DELAYED; trust 35. The crew pauses the decision while battery reserves continue to fall. | Y18: =O18&" answer | Retrieval "&P18&"% | Ranking "&Q18&"% | Grounding "&R18&"% | Citation "&S18&"% | Hallucination Risk "&T18&"% | Trust "&U18&"%" -> Partial answer | Retrieval 50% | Ranking 70% | Grounding 60% | Citation 50% | Hallucination Risk 40% | Trust 58% | AA18: Not Run
A19: R-solar_shield-14 | B19: solar_shield | C19: Solar Shield Battery Check | D19: Can we activate the solar shield during low battery mode? | E19: D1 | F19: oxygen_backup_power: The oxygen system uses backup power during low battery mode. | G19: K1 | H19: shield_power_requirement: The solar shield requires the battery level to be above 40%. | I19: D2 | J19: radiation_protection: The solar shield protects the ship during radiation storms. | K19: K2 | L19: low_battery_threshold: Low battery mode begins when the battery level falls below 25%. | M19: =IF(E19="K1",1,IF(G19="K1",2,IF(I19="K1",3,4))) -> 2 | N19: =IF(E19="K2",1,IF(G19="K2",2,IF(I19="K2",3,4))) -> 4 | O19: =IF(AND(M19<=2,N19<=2),"Grounded",IF(OR(M19<=2,N19<=2),"Partial","Risky")) -> Partial | P19: =IF(O19="Grounded",100,IF(O19="Partial",50,0)) -> 50 | Q19: =MAX(0,50-ABS(M19-1)*15)+MAX(0,50-ABS(N19-2)*15) -> 55 | R19: =IF(O19="Grounded",100,IF(O19="Partial",60,10)) -> 60 | S19: =IF(O19="Grounded",100,IF(O19="Partial",50,0)) -> 50 | T19: =IF(O19="Grounded",0,IF(O19="Partial",40,90)) -> 40 | U19: =ROUND((P19+Q19+R19+S19+(100-T19))/5,0) -> 55 | V19: =O19 -> Partial | W19: =IF(O19="Grounded","MISSION SUCCESS: The shield remains offline. Battery power is preserved for essential systems.",IF(O19="Partial","MISSION PROTECTED: Response held for more evidence; Try New Mission.","RISK BLOCKED: Unsupported action prevented; Try New Mission.")) -> MISSION PROTECTED: Response held for more evidence; Try New Mission. | X19: =IF(O19="Grounded","MISSION SUCCESS + PROCESS WARNING; trust 70. The shield remains offline. Battery power is preserved for essential systems.",IF(O19="Partial","MISSION DELAYED; trust 35. The crew pauses the decision while battery reserves continue to fall.","GAME OVER; trust 5. The shield overloads the low-battery system and causes a shipwide power emergency.")) -> MISSION DELAYED; trust 35. The crew pauses the decision while battery reserves continue to fall. | Y19: =O19&" answer | Retrieval "&P19&"% | Ranking "&Q19&"% | Grounding "&R19&"% | Citation "&S19&"% | Hallucination Risk "&T19&"% | Trust "&U19&"%" -> Partial answer | Retrieval 50% | Ranking 55% | Grounding 60% | Citation 50% | Hallucination Risk 40% | Trust 55% | AA19: Not Run
... A29: R-solar_shield-24 | B29: solar_shield | C29: Solar Shield Battery Check | D29: Can we activate the solar shield during low battery mode? | E29: D2 | F29: radiation_protection: The solar shield protects the ship during radiation storms. | G29: D1 | H29: oxygen_backup_power: The oxygen system uses backup power during low battery mode. | I29: K2 | J29: low_battery_threshold: Low battery mode begins when the battery level falls below 25%. | K29: K1 | L29: shield_power_requirement: The solar shield requires the battery level to be above 40%. | M29: =IF(E29="K1",1,IF(G29="K1",2,IF(I29="K1",3,4))) -> 4 | N29: =IF(E29="K2",1,IF(G29="K2",2,IF(I29="K2",3,4))) -> 3 | O29: =IF(AND(M29<=2,N29<=2),"Grounded",IF(OR(M29<=2,N29<=2),"Partial","Risky")) -> Risky | P29: =IF(O29="Grounded",100,IF(O29="Partial",50,0)) -> 0 | Q29: =MAX(0,50-ABS(M29-1)*15)+MAX(0,50-ABS(N29-2)*15) -> 40 | R29: =IF(O29="Grounded",100,IF(O29="Partial",60,10)) -> 10 | S29: =IF(O29="Grounded",100,IF(O29="Partial",50,0)) -> 0 | T29: =IF(O29="Grounded",0,IF(O29="Partial",40,90)) -> 90 | U29: =ROUND((P29+Q29+R29+S29+(100-T29))/5,0) -> 12 | V29: =O29 -> Risky | W29: =IF(O29="Grounded","MISSION SUCCESS: The shield remains offline. Battery power is preserved for essential systems.",IF(O29="Partial","MISSION PROTECTED: Response held for more evidence; Try New Mission.","RISK BLOCKED: Unsupported action prevented; Try New Mission.")) -> RISK BLOCKED: Unsupported action prevented; Try New Mission. | X29: =IF(O29="Grounded","MISSION SUCCESS + PROCESS WARNING; trust 70. The shield remains offline. Battery power is preserved for essential systems.",IF(O29="Partial","MISSION DELAYED; trust 35. The crew pauses the decision while battery reserves continue to fall.","GAME OVER; trust 5. The shield overloads the low-battery system and causes a shipwide power emergency.")) -> GAME OVER; trust 5. The shield overloads the low-battery system and causes a shipwide power emergency. | Y29: =O29&" answer | Retrieval "&P29&"% | Ranking "&Q29&"% | Grounding "&R29&"% | Citation "&S29&"% | Hallucination Risk "&T29&"% | Trust "&U29&"%" -> Risky answer | Retrieval 0% | Ranking 40% | Grounding 10% | Citation 0% | Hallucination Risk 90% | Trust 12% | AA29: Not Run
A30: R-cargo_bay-01 | B30: cargo_bay | C30: Cargo Bay Safety Check | D30: Can we open the exterior cargo bay while the ship is moving at cruise speed? | E30: K1 | F30: cargo_speed_requirement: Exterior cargo bay doors may open only when the ship speed is zero. | G30: K2 | H30: cruise_speed_status: Cruise mode keeps the ship moving above 5,000 kilometers per hour. | I30: D1 | J30: cargo_contents: The cargo bay stores repair drones and spare equipment. | K30: D2 | L30: docking_clamps: Docking clamps engage automatically near a space station. | M30: =IF(E30="K1",1,IF(G30="K1",2,IF(I30="K1",3,4))) -> 1 | N30: =IF(E30="K2",1,IF(G30="K2",2,IF(I30="K2",3,4))) -> 2 | O30: =IF(AND(M30<=2,N30<=2),"Grounded",IF(OR(M30<=2,N30<=2),"Partial","Risky")) -> Grounded | P30: =IF(O30="Grounded",100,IF(O30="Partial",50,0)) -> 100 | Q30: =MAX(0,50-ABS(M30-1)*15)+MAX(0,50-ABS(N30-2)*15) -> 100 | R30: =IF(O30="Grounded",100,IF(O30="Partial",60,10)) -> 100 | S30: =IF(O30="Grounded",100,IF(O30="Partial",50,0)) -> 100 | T30: =IF(O30="Grounded",0,IF(O30="Partial",40,90)) -> 0 | U30: =ROUND((P30+Q30+R30+S30+(100-T30))/5,0) -> 100 | V30: =O30 -> Grounded | W30: =IF(O30="Grounded","MISSION SUCCESS: The cargo bay remains sealed until the ship stops, preventing decompression and equipment loss.",IF(O30="Partial","MISSION PROTECTED: Response held for more evidence; Try New Mission.","RISK BLOCKED: Unsupported action prevented; Try New Mission.")) -> MISSION SUCCESS: The cargo bay remains sealed until the ship stops, preventing decompression and equipment loss. | X30: =IF(O30="Grounded","MISSION SUCCESS + PROCESS WARNING; trust 70. The cargo bay remains sealed until the ship stops, preventing decompression and equipment loss.",IF(O30="Partial","MISSION DELAYED; trust 35. The crew pauses the cargo operation while confirming the ship-speed requirement.","GAME OVER; trust 5. The cargo bay opens at cruise speed, causing rapid decompression and the loss of critical equipment.")) -> MISSION SUCCESS + PROCESS WARNING; trust 70. The cargo bay remains sealed until the ship stops, preventing decompression and equipment loss. | Y30: =O30&" answer | Retrieval "&P30&"% | Ranking "&Q30&"% | Grounding "&R30&"% | Citation "&S30&"% | Hallucination Risk "&T30&"% | Trust "&U30&"%" -> Grounded answer | Retrieval 100% | Ranking 100% | Grounding 100% | Citation 100% | Hallucination Risk 0% | Trust 100% | AA30: Not Run
A31: R-cargo_bay-02 | B31: cargo_bay | C31: Cargo Bay Safety Check | D31: Can we open the exterior cargo bay while the ship is moving at cruise speed? | E31: K1 | F31: cargo_speed_requirement: Exterior cargo bay doors may open only when the ship speed is zero. | G31: K2 | H31: cruise_speed_status: Cruise mode keeps the ship moving above 5,000 kilometers per hour. | I31: D2 | J31: docking_clamps: Docking clamps engage automatically near a space station. | K31: D1 | L31: cargo_contents: The cargo bay stores repair drones and spare equipment. | M31: =IF(E31="K1",1,IF(G31="K1",2,IF(I31="K1",3,4))) -> 1 | N31: =IF(E31="K2",1,IF(G31="K2",2,IF(I31="K2",3,4))) -> 2 | O31: =IF(AND(M31<=2,N31<=2),"Grounded",IF(OR(M31<=2,N31<=2),"Partial","Risky")) -> Grounded | P31: =IF(O31="Grounded",100,IF(O31="Partial",50,0)) -> 100 | Q31: =MAX(0,50-ABS(M31-1)*15)+MAX(0,50-ABS(N31-2)*15) -> 100 | R31: =IF(O31="Grounded",100,IF(O31="Partial",60,10)) -> 100 | S31: =IF(O31="Grounded",100,IF(O31="Partial",50,0)) -> 100 | T31: =IF(O31="Grounded",0,IF(O31="Partial",40,90)) -> 0 | U31: =ROUND((P31+Q31+R31+S31+(100-T31))/5,0) -> 100 | V31: =O31 -> Grounded | W31: =IF(O31="Grounded","MISSION SUCCESS: The cargo bay remains sealed until the ship stops, preventing decompression and equipment loss.",IF(O31="Partial","MISSION PROTECTED: Response held for more evidence; Try New Mission.","RISK BLOCKED: Unsupported action prevented; Try New Mission.")) -> MISSION SUCCESS: The cargo bay remains sealed until the ship stops, preventing decompression and equipment loss. | X31: =IF(O31="Grounded","MISSION SUCCESS + PROCESS WARNING; trust 70. The cargo bay remains sealed until the ship stops, preventing decompression and equipment loss.",IF(O31="Partial","MISSION DELAYED; trust 35. The crew pauses the cargo operation while confirming the ship-speed requirement.","GAME OVER; trust 5. The cargo bay opens at cruise speed, causing rapid decompression and the loss of critical equipment.")) -> MISSION SUCCESS + PROCESS WARNING; trust 70. The cargo bay remains sealed until the ship stops, preventing decompression and equipment loss. | Y31: =O31&" answer | Retrieval "&P31&"% | Ranking "&Q31&"% | Grounding "&R31&"% | Citation "&S31&"% | Hallucination Risk "&T31&"% | Trust "&U31&"%" -> Grounded answer | Retrieval 100% | Ranking 100% | Grounding 100% | Citation 100% | Hallucination Risk 0% | Trust 100% | AA31: Not Run
A32: R-cargo_bay-03 | B32: cargo_bay | C32: Cargo Bay Safety Check | D32: Can we open the exterior cargo bay while the ship is moving at cruise speed? | E32: K1 | F32: cargo_speed_requirement: Exterior cargo bay doors may open only when the ship speed is zero. | G32: D1 | H32: cargo_contents: The cargo bay stores repair drones and spare equipment. | I32: K2 | J32: cruise_speed_status: Cruise mode keeps the ship moving above 5,000 kilometers per hour. | K32: D2 | L32: docking_clamps: Docking clamps engage automatically near a space station. | M32: =IF(E32="K1",1,IF(G32="K1",2,IF(I32="K1",3,4))) -> 1 | N32: =IF(E32="K2",1,IF(G32="K2",2,IF(I32="K2",3,4))) -> 3 | O32: =IF(AND(M32<=2,N32<=2),"Grounded",IF(OR(M32<=2,N32<=2),"Partial","Risky")) -> Partial | P32: =IF(O32="Grounded",100,IF(O32="Partial",50,0)) -> 50 | Q32: =MAX(0,50-ABS(M32-1)*15)+MAX(0,50-ABS(N32-2)*15) -> 85 | R32: =IF(O32="Grounded",100,IF(O32="Partial",60,10)) -> 60 | S32: =IF(O32="Grounded",100,IF(O32="Partial",50,0)) -> 50 | T32: =IF(O32="Grounded",0,IF(O32="Partial",40,90)) -> 40 | U32: =ROUND((P32+Q32+R32+S32+(100-T32))/5,0) -> 61 | V32: =O32 -> Partial | W32: =IF(O32="Grounded","MISSION SUCCESS: The cargo bay remains sealed until the ship stops, preventing decompression and equipment loss.",IF(O32="Partial","MISSION PROTECTED: Response held for more evidence; Try New Mission.","RISK BLOCKED: Unsupported action prevented; Try New Mission.")) -> MISSION PROTECTED: Response held for more evidence; Try New Mission. | X32: =IF(O32="Grounded","MISSION SUCCESS + PROCESS WARNING; trust 70. The cargo bay remains sealed until the ship stops, preventing decompression and equipment loss.",IF(O32="Partial","MISSION DELAYED; trust 35. The crew pauses the cargo operation while confirming the ship-speed requirement.","GAME OVER; trust 5. The cargo bay opens at cruise speed, causing rapid decompression and the loss of critical equipment.")) -> MISSION DELAYED; trust 35. The crew pauses the cargo operation while confirming the ship-speed requirement. | Y32: =O32&" answer | Retrieval "&P32&"% | Ranking "&Q32&"% | Grounding "&R32&"% | Citation "&S32&"% | Hallucination Risk "&T32&"% | Trust "&U32&"%" -> Partial answer | Retrieval 50% | Ranking 85% | Grounding 60% | Citation 50% | Hallucination Risk 40% | Trust 61% | AA32: Not Run
A33: R-cargo_bay-04 | B33: cargo_bay | C33: Cargo Bay Safety Check | D33: Can we open the exterior cargo bay while the ship is moving at cruise speed? | E33: K1 | F33: cargo_speed_requirement: Exterior cargo bay doors may open only when the ship speed is zero. | G33: D1 | H33: cargo_contents: The cargo bay stores repair drones and spare equipment. | I33: D2 | J33: docking_clamps: Docking clamps engage automatically near a space station. | K33: K2 | L33: cruise_speed_status: Cruise mode keeps the ship moving above 5,000 kilometers per hour. | M33: =IF(E33="K1",1,IF(G33="K1",2,IF(I33="K1",3,4))) -> 1 | N33: =IF(E33="K2",1,IF(G33="K2",2,IF(I33="K2",3,4))) -> 4 | O33: =IF(AND(M33<=2,N33<=2),"Grounded",IF(OR(M33<=2,N33<=2),"Partial","Risky")) -> Partial | P33: =IF(O33="Grounded",100,IF(O33="Partial",50,0)) -> 50 | Q33: =MAX(0,50-ABS(M33-1)*15)+MAX(0,50-ABS(N33-2)*15) -> 70 | R33: =IF(O33="Grounded",100,IF(O33="Partial",60,10)) -> 60 | S33: =IF(O33="Grounded",100,IF(O33="Partial",50,0)) -> 50 | T33: =IF(O33="Grounded",0,IF(O33="Partial",40,90)) -> 40 | U33: =ROUND((P33+Q33+R33+S33+(100-T33))/5,0) -> 58 | V33: =O33 -> Partial | W33: =IF(O33="Grounded","MISSION SUCCESS: The cargo bay remains sealed until the ship stops, preventing decompression and equipment loss.",IF(O33="Partial","MISSION PROTECTED: Response held for more evidence; Try New Mission.","RISK BLOCKED: Unsupported action prevented; Try New Mission.")) -> MISSION PROTECTED: Response held for more evidence; Try New Mission. | X33: =IF(O33="Grounded","MISSION SUCCESS + PROCESS WARNING; trust 70. The cargo bay remains sealed until the ship stops, preventing decompression and equipment loss.",IF(O33="Partial","MISSION DELAYED; trust 35. The crew pauses the cargo operation while confirming the ship-speed requirement.","GAME OVER; trust 5. The cargo bay opens at cruise speed, causing rapid decompression and the loss of critical equipment.")) -> MISSION DELAYED; trust 35. The crew pauses the cargo operation while confirming the ship-speed requirement. | Y33: =O33&" answer | Retrieval "&P33&"% | Ranking "&Q33&"% | Grounding "&R33&"% | Citation "&S33&"% | Hallucination Risk "&T33&"% | Trust "&U33&"%" -> Partial answer | Retrieval 50% | Ranking 70% | Grounding 60% | Citation 50% | Hallucination Risk 40% | Trust 58% | AA33: Not Run
A34: R-cargo_bay-05 | B34: cargo_bay | C34: Cargo Bay Safety Check | D34: Can we open the exterior cargo bay while the ship is moving at cruise speed? | E34: K1 | F34: cargo_speed_requirement: Exterior cargo bay doors may open only when the ship speed is zero. | G34: D2 | H34: docking_clamps: Docking clamps engage automatically near a space station. | I34: K2 | J34: cruise_speed_status: Cruise mode keeps the ship moving above 5,000 kilometers per hour. | K34: D1 | L34: cargo_contents: The cargo bay stores repair drones and spare equipment. | M34: =IF(E34="K1",1,IF(G34="K1",2,IF(I34="K1",3,4))) -> 1 | N34: =IF(E34="K2",1,IF(G34="K2",2,IF(I34="K2",3,4))) -> 3 | O34: =IF(AND(M34<=2,N34<=2),"Grounded",IF(OR(M34<=2,N34<=2),"Partial","Risky")) -> Partial | P34: =IF(O34="Grounded",100,IF(O34="Partial",50,0)) -> 50 | Q34: =MAX(0,50-ABS(M34-1)*15)+MAX(0,50-ABS(N34-2)*15) -> 85 | R34: =IF(O34="Grounded",100,IF(O34="Partial",60,10)) -> 60 | S34: =IF(O34="Grounded",100,IF(O34="Partial",50,0)) -> 50 | T34: =IF(O34="Grounded",0,IF(O34="Partial",40,90)) -> 40 | U34: =ROUND((P34+Q34+R34+S34+(100-T34))/5,0) -> 61 | V34: =O34 -> Partial | W34: =IF(O34="Grounded","MISSION SUCCESS: The cargo bay remains sealed until the ship stops, preventing decompression and equipment loss.",IF(O34="Partial","MISSION PROTECTED: Response held for more evidence; Try New Mission.","RISK BLOCKED: Unsupported action prevented; Try New Mission.")) -> MISSION PROTECTED: Response held for more evidence; Try New Mission. | X34: =IF(O34="Grounded","MISSION SUCCESS + PROCESS WARNING; trust 70. The cargo bay remains sealed until the ship stops, preventing decompression and equipment loss.",IF(O34="Partial","MISSION DELAYED; trust 35. The crew pauses the cargo operation while confirming the ship-speed requirement.","GAME OVER; trust 5. The cargo bay opens at cruise speed, causing rapid decompression and the loss of critical equipment.")) -> MISSION DELAYED; trust 35. The crew pauses the cargo operation while confirming the ship-speed requirement. | Y34: =O34&" answer | Retrieval "&P34&"% | Ranking "&Q34&"% | Grounding "&R34&"% | Citation "&S34&"% | Hallucination Risk "&T34&"% | Trust "&U34&"%" -> Partial answer | Retrieval 50% | Ranking 85% | Grounding 60% | Citation 50% | Hallucination Risk 40% | Trust 61% | AA34: Not Run
